Workbook
Name Abr2_: '[1]Consolidado M.Preventivo'!#REF!
Name ABRI: '[1]Consolidado M.Preventivo'!#REF!
Name Ago2_: '[1]Consolidado M.Preventivo'!#REF!
Name agos: '[1]Consolidado M.Preventivo'!#REF!
Name CONSOLIDADO: '[2]Consolidado M.Preventivo'!#REF!
Name Correlativo: '[1]Consolidado M.Preventivo'!#REF!
Name Cumplimiento: '[1]Consolidado M.Preventivo'!#REF!
Name Dic2_: '[1]Consolidado M.Preventivo'!#REF!
Name Ene2_: '[1]Consolidado M.Preventivo'!#REF!
Name Feb2_: '[1]Consolidado M.Preventivo'!#REF!
Name Jul2_: '[1]Consolidado M.Preventivo'!#REF!
Name Jun2_: '[1]Consolidado M.Preventivo'!#REF!
Name Mantenimiento_N°_2: '[1]Consolidado M.Preventivo'!#REF!
Name Mantenimiento_N°1: '[1]Consolidado M.Preventivo'!#REF!
Name Mantenimiento_N°3: '[1]Consolidado M.Preventivo'!#REF!
Name Mar2_: '[1]Consolidado M.Preventivo'!#REF!
Name May2_: '[1]Consolidado M.Preventivo'!#REF!
Name Nov2_: '[1]Consolidado M.Preventivo'!#REF!
Name nproducto: [3]NPRODUCTOS!$J$9:$U$7009
Name Oct2_: '[1]Consolidado M.Preventivo'!#REF!
Name Proveedor_Adjudicado: '[1]Consolidado M.Preventivo'!#REF!
Name Sep2_: '[1]Consolidado M.Preventivo'!#REF!
Name Total_MP: '[1]Consolidado M.Preventivo'!#REF!
Name Total_Periodo: '[1]Consolidado M.Preventivo'!#REF!
Name Vida_Útil: #REF!
Name Vida_Útil_Residual: #REF!

Sheet CATASTRO Y PLANIFICACIÓN MP
Y1: X | Z1: PROGRAMADO
Y2: √ | Z2: REALIZADO | AH2: √
A3: SERVICIO DE SALUD | B3: METROPOLITANO CENTRAL | Y3: ꓣ | Z3: REPROGRAMADO
AD4: √
A5: NOMBRE ESTABLECIMIENTO | B5: HOSPITAL EL CARMEN DR. LUIS VALENTÍN FERRADA
A7: RESPONSABLE TÉCNICO | B7: FRANCISCO OLIVA | X7: MONITOREO MENSUAL DEL PLAN
X8: % EJECUCIÓN MP TOTAL MENSUAL | Y8: =+'TABLA CÁLCULO'!B24 | Z8: =+'TABLA CÁLCULO'!C24 | AA8: =+'TABLA CÁLCULO'!D24 | AB8: =+'TABLA CÁLCULO'!E24 | AC8: =+'TABLA CÁLCULO'!F24 | AD8: =+'TABLA CÁLCULO'!G24 | AE8: =+'TABLA CÁLCULO'!H24 | AF8: =+'TABLA CÁLCULO'!I24 | ... AJ8: =+'TABLA CÁLCULO'!M24
A9: AÑO DE LEVANTAMIENTO | B9: 2026 | X9: % EJECUCIÓN MP EQC MENSUAL | Y9: =+'TABLA CÁLCULO'!B25 | Z9: =+'TABLA CÁLCULO'!C25 | AA9: =+'TABLA CÁLCULO'!D25 | AB9: =+'TABLA CÁLCULO'!E25 | AC9: =+'TABLA CÁLCULO'!F25 | AD9: =+'TABLA CÁLCULO'!G25 | AE9: =+'TABLA CÁLCULO'!H25 | AF9: =+'TABLA CÁLCULO'!I25 | ... AJ9: =+'TABLA CÁLCULO'!M25
C10: =UPPER(B:E) -> 0 | X10: % EJECUCIÓN MP EQR MENSUAL | Y10: =+'TABLA CÁLCULO'!B26 | Z10: =+'TABLA CÁLCULO'!C26 | AA10: =+'TABLA CÁLCULO'!D26 | AB10: =+'TABLA CÁLCULO'!E26 | AC10: =+'TABLA CÁLCULO'!F26 | AD10: =+'TABLA CÁLCULO'!G26 | AE10: =+'TABLA CÁLCULO'!H26 | AF10: =+'TABLA CÁLCULO'!I26 | ... AJ10: =+'TABLA CÁLCULO'!M26
A11: GASTO PROGRAMADO MP | B11: 2160000000 | D11: EJECUCIÓN GASTO MP | X11: % EJECUCIÓN MP IM≥12 MENSUAL | Y11: =+'TABLA CÁLCULO'!B27 | Z11: =+'TABLA CÁLCULO'!C27 | AA11: =+'TABLA CÁLCULO'!D27 | AB11: =+'TABLA CÁLCULO'!E27 | AC11: =+'TABLA CÁLCULO'!F27 | AD11: =+'TABLA CÁLCULO'!G27 | AE11: =+'TABLA CÁLCULO'!H27 | AF11: =+'TABLA CÁLCULO'!I27 | ... AJ11: =+'TABLA CÁLCULO'!M27
A13: GASTO PROGRAMADO MC | B13: 960000000 | D13: EJECUCIÓN GASTO MC | Q13: % EJECUCIÓN GASTO MP | T13: % EJECUCIÓN GASTO MC
Y14: CUMPLIMIENTO MANTENIMIENTO PREVENTIVO | AK14: EJECUCIÓN MANTENIMIENTO PREVENTIVO HEC
A15: SERVICIO CLÍNICO | B15: RECINTO | C15: CLASE | D15: SUBCLASE | E15: NOMBRE EQUIPO | F15: MARCA | G15: MODELO | H15: SERIE | I15: N° INVENTARIO | J15: AÑO DE ADQUISICIÓN | K15: VIDA ÚTIL | L15: VIDA ÚTIL RESIDUAL | M15: PROPIO / ARRIENDO / COMODATO | N15: ESTADO (BUENO / REGULAR / MALO / BAJA) | O15: CRÍTICO/ RELEVANTE / IM≥12 / NO APLICA | P15: EN GARANTÍA (SI / NO) | Q15: AÑO VENCIMIENTO GARANTÍA | R15: BAJO PLAN DE MANTENIMIENTO (SI / NO) | S15: AÑO INGRESO A PLAN DE MANTENIMIENTO (2023 / 2024 / 2025 / 2026) | T15: MANTENIMIENTO INTERNO O MANTENIMIENTO EXTERNO O CONTRATO | U15: NOMBRE DE PROVEEDOR O MANTENIMIENTO INTERNO | V15: ID CONVENIO DE MANTENIMIENTO / ID DE REFERENCIA / COTIZACIÓN DE REFERENCIA | W15: COSTO ANUAL DE MANTENIMIENTO SEGÚN CONVENIO / PRECIO DE REFERENCIA MANTENIMIENTO ANUAL | X15: FRECUENCIA ANUAL DE MANTENIMIENTO | Y15: ENERO | Z15: FEBRERO | AA15: MARZO | AB15: ABRIL | AC15: MAYO | AD15: JUNIO | AE15: JULIO | AF15: AGOSTO | AG15: SEPTIEMBRE | AH15: OCTUBRE | AI15: NOVIEMBRE | AJ15: DICIEMBRE | AK15: ENERO | AL15: FEBRERO | AM15: MARZO | AN15: ABRIL | AO15: MAYO | AP15: JUNIO | AQ15: JULIO | AR15: AGOSTO | AS15: SEPTIEMBRE | AT15: OCTUBRE | AU15: NOVIEMBRE | AV15: DICIEMBRE
A16: HOSPITALIZACIÓN DOMICILIARIA | B16: PISO 3 | C16: APOYO TERAPÉUTICO | D16: BAJO COSTO | E16: Bomba de Aspiración | F16: Yuwell | G16: Yuwell 7E-C/G | H16: S/I | I16: 500000010669 | J16: 2021 | K16: 5 | L16: =IF(AND(J16=0,K16=0),"",K16-($B$9-J16)) -> 0 | M16: PROPIO | N16: BUENO | O16: NO APLICA | P16: NO | Q16: NO APLICA | R16: NO | S16: S/I | T16: INTERNO | U16: HOSPITAL & MEDICAL SOLUTIONS S.A. | V16: S/I | W16: 0
A17: INGENIERÍA BIOMÉDICA | B17: PISO -1 | C17: MONITOREO | D17: ALTO COSTO | E17: Monitor Signos Vitales | F17: Spacelabs | G17: Xprezzon | H17: PSC-19430020B | I17: 500000010342 | J17: 2020 | K17: 8 | L17: =IF(AND(J17=0,K17=0),"",K17-($B$9-J17)) -> 2 | M17: PROPIO | N17: BUENO | O17: Crítico | P17: NO | Q17: NO APLICA | R17: SI | S17: 2023 | T17: CONTRATO | U17: Hemisferio Sur S.A | V17: 1057472-9-LQ25 | W17: 130904.37 | X17: 2 | AC17: X | AI17: X | AO17: MP | AU17: MP
A18: INGENIERÍA BIOMÉDICA | B18: PISO -1 | C18: MONITOREO | D18: ALTO COSTO | E18: Monitor Signos Vitales | F18: Spacelabs | G18: Xprezzon | H18: PSC-19360043B | I18: 500000010343 | J18: 2020 | K18: 8 | L18: =IF(AND(J18=0,K18=0),"",K18-($B$9-J18)) -> 2 | M18: PROPIO | N18: BUENO | O18: Crítico | P18: NO | Q18: NO APLICA | R18: SI | S18: 2023 | T18: CONTRATO | U18: Hemisferio Sur S.A | V18: 1057472-9-LQ25 | W18: 130904.37 | X18: 2 | AC18: X | AI18: X | AO18: MP | AU18: MP
A19: INGENIERÍA BIOMÉDICA | B19: PISO -1 | C19: MONITOREO | D19: ALTO COSTO | E19: Monitor Signos Vitales | F19: Spacelabs | G19: Xprezzon | H19: PSC-19360034B | I19: 500000010344 | J19: 2020 | K19: 8 | L19: =IF(AND(J19=0,K19=0),"",K19-($B$9-J19)) -> 2 | M19: PROPIO | N19: BUENO | O19: Crítico | P19: NO | Q19: NO APLICA | R19: SI | S19: 2023 | T19: CONTRATO | U19: Hemisferio Sur S.A | V19: 1057472-9-LQ25 | W19: 130904.37 | X19: 2 | AC19: X | AI19: X | AO19: MP | AU19: MP
A20: EMERGENCIA ADULTO | B20: PISO 1 | C20: MONITOREO | D20: ALTO COSTO | E20: Monitor Signos Vitales | F20: Spacelabs | G20: Xprezzon | H20: PSC-19430070B | I20: 500000010345 | J20: 2020 | K20: 8 | L20: =IF(AND(J20=0,K20=0),"",K20-($B$9-J20)) -> 2 | M20: PROPIO | N20: BUENO | O20: Crítico | P20: NO | Q20: NO APLICA | R20: SI | S20: 2023 | T20: CONTRATO | U20: Hemisferio Sur S.A | V20: 1057472-9-LQ25 | W20: 130904.37 | X20: 2 | AC20: X | AI20: X | AO20: MP | AU20: MP
A21: EMERGENCIA ADULTO | B21: PISO 1 | C21: MONITOREO | D21: ALTO COSTO | E21: Monitor Signos Vitales | F21: Spacelabs | G21: Xprezzon | H21: PRO-19370433B | I21: 500000010391 | J21: 2020 | K21: 8 | L21: =IF(AND(J21=0,K21=0),"",K21-($B$9-J21)) -> 2 | M21: PROPIO | N21: BUENO | O21: Crítico | P21: NO | Q21: NO APLICA | R21: SI | S21: 2023 | T21: CONTRATO | U21: Hemisferio Sur S.A | V21: 1057472-9-LQ25 | W21: 130904.37 | X21: 2 | AC21: X | AI21: X | AO21: MP | AU21: MP
A22: EMERGENCIA ADULTO | B22: PISO 1 | C22: MONITOREO | D22: ALTO COSTO | E22: Monitor Signos Vitales | F22: Spacelabs | G22: Xprezzon | H22: PRO-19370116B | I22: 500000010390 | J22: 2020 | K22: 8 | L22: =IF(AND(J22=0,K22=0),"",K22-($B$9-J22)) -> 2 | M22: PROPIO | N22: BUENO | O22: Crítico | P22: NO | Q22: NO APLICA | R22: SI | S22: 2023 | T22: CONTRATO | U22: Hemisferio Sur S.A | V22: 1057472-9-LQ25 | W22: 130904.37 | X22: 2 | AC22: X | AI22: X | AO22: MP | AU22: MP
A23: EMERGENCIA ADULTO | B23: PISO 1 | C23: MONITOREO | D23: ALTO COSTO | E23: Monitor Signos Vitales | F23: Spacelabs | G23: Xprezzon | H23: PRO-19370160B | I23: 500000010393 | J23: 2020 | K23: 8 | L23: =IF(AND(J23=0,K23=0),"",K23-($B$9-J23)) -> 2 | M23: PROPIO | N23: BUENO | O23: Crítico | P23: NO | Q23: NO APLICA | R23: SI | S23: 2023 | T23: CONTRATO | U23: Hemisferio Sur S.A | V23: 1057472-9-LQ25 | W23: 130904.37 | X23: 2 | AC23: X | AI23: X | AO23: MP | AU23: MP
A24: EMERGENCIA ADULTO | B24: PISO 1 | C24: MONITOREO | D24: ALTO COSTO | E24: Monitor Signos Vitales | F24: Spacelabs | G24: Xprezzon | H24: PRO-19370134B | I24: 500000010392 | J24: 2020 | K24: 8 | L24: =IF(AND(J24=0,K24=0),"",K24-($B$9-J24)) -> 2 | M24: PROPIO | N24: BUENO | O24: Crítico | P24: NO | Q24: NO APLICA | R24: SI | S24: 2023 | T24: CONTRATO | U24: Hemisferio Sur S.A | V24: 1057472-9-LQ25 | W24: 130904.37 | X24: 2 | AC24: X | AI24: X | AO24: MP | AU24: MP
A25: HOSPITALIZACIÓN QUIRÚRGICA | B25: PISO 4 | C25: MONITOREO | D25: MEDIANO COSTO | E25: Monitor Signos Vitales | F25: EDAN | G25: X12 | H25: 261594-M21307950004 | I25: 500000010738 | J25: 2021 | K25: 8 | L25: =IF(AND(J25=0,K25=0),"",K25-($B$9-J25)) -> 3 | M25: PROPIO | N25: BUENO | O25: Crítico | P25: NO | Q25: NO APLICA | R25: SI | S25: 2023 | T25: CONTRATO | U25: INNOVAMEDICA | V25: 1057472-9-LQ25 | W25: 130904.37 | X25: 2 | AB25: X | AH25: X | AN25: MP | AT25: MP
A26: MEDICINA | B26: PISO 4 | C26: MONITOREO | D26: MEDIANO COSTO | E26: Monitor Signos Vitales | F26: EDAN | G26: X12 | H26: 261594-M21308370008 | I26: 500000010739 | J26: 2021 | K26: 8 | L26: =IF(AND(J26=0,K26=0),"",K26-($B$9-J26)) -> 3 | M26: PROPIO | N26: BUENO | O26: Crítico | P26: NO | Q26: NO APLICA | R26: SI | S26: 2023 | T26: CONTRATO | U26: INNOVAMEDICA | V26: 1057472-9-LQ25 | W26: 130904.37 | X26: 2 | AB26: X | AH26: X | AN26: MP | AT26: MP
A27: MEDICINA | B27: PISO 4 | C27: MONITOREO | D27: MEDIANO COSTO | E27: Monitor Signos Vitales | F27: EDAN | G27: X12 | H27: 261594-M21308370045 | I27: 500000010740 | J27: 2021 | K27: 8 | L27: =IF(AND(J27=0,K27=0),"",K27-($B$9-J27)) -> 3 | M27: PROPIO | N27: BUENO | O27: Crítico | P27: NO | Q27: NO APLICA | R27: SI | S27: 2023 | T27: CONTRATO | U27: INNOVAMEDICA | V27: 1057472-9-LQ25 | W27: 130904.37 | X27: 2 | AB27: X | AH27: X | AN27: MP | AT27: MP
A28: MEDICINA | B28: PISO 4 | C28: MONITOREO | D28: MEDIANO COSTO | E28: Monitor Signos Vitales | F28: EDAN | G28: X12 | H28: 261594-M21308370009 | I28: 500000010741 | J28: 2021 | K28: 8 | L28: =IF(AND(J28=0,K28=0),"",K28-($B$9-J28)) -> 3 | M28: PROPIO | N28: BUENO | O28: Crítico | P28: NO | Q28: NO APLICA | R28: SI | S28: 2023 | T28: CONTRATO | U28: INNOVAMEDICA | V28: 1057472-9-LQ25 | W28: 130904.37 | X28: 2 | AB28: X | AH28: X | AN28: MP | AT28: MP
A29: MEDICINA | B29: PISO 4 | C29: MONITOREO | D29: MEDIANO COSTO | E29: Monitor Signos Vitales | F29: EDAN | G29: X12 | H29: 261594-M21308370044 | I29: 500000010742 | J29: 2021 | K29: 8 | L29: =IF(AND(J29=0,K29=0),"",K29-($B$9-J29)) -> 3 | M29: PROPIO | N29: BUENO | O29: Crítico | P29: NO | Q29: NO APLICA | R29: SI | S29: 2023 | T29: CONTRATO | U29: INNOVAMEDICA | V29: 1057472-9-LQ25 | W29: 130904.37 | X29: 2 | AB29: X | AH29: X | AN29: MP | AT29: MP
A30: MEDICINA | B30: PISO 4 | C30: MONITOREO | D30: MEDIANO COSTO | E30: Monitor Signos Vitales | F30: EDAN | G30: X12 | H30: 261594-M21308370033 | I30: 500000010743 | J30: 2021 | K30: 8 | L30: =IF(AND(J30=0,K30=0),"",K30-($B$9-J30)) -> 3 | M30: PROPIO | N30: BUENO | O30: Crítico | P30: NO | Q30: NO APLICA | R30: SI | S30: 2023 | T30: CONTRATO | U30: INNOVAMEDICA | V30: 1057472-9-LQ25 | W30: 130904.37 | X30: 2 | AB30: X | AH30: X | AN30: MP | AT30: MP
A31: MEDICINA | B31: PISO 4 | C31: MONITOREO | D31: MEDIANO COSTO | E31: Monitor Signos Vitales | F31: EDAN | G31: X12 | H31: 261594-M21308370007 | I31: 500000010744 | J31: 2021 | K31: 8 | L31: =IF(AND(J31=0,K31=0),"",K31-($B$9-J31)) -> 3 | M31: PROPIO | N31: BUENO | O31: Crítico | P31: NO | Q31: NO APLICA | R31: SI | S31: 2023 | T31: CONTRATO | U31: INNOVAMEDICA | V31: 1057472-9-LQ25 | W31: 130904.37 | X31: 2 | AB31: X | AH31: X | AN31: MP | AT31: MP
A32: MEDICINA | B32: PISO 4 | C32: MONITOREO | D32: MEDIANO COSTO | E32: Monitor Signos Vitales | F32: EDAN | G32: X12 | H32: 261594-M21308370043 | I32: 500000010745 | J32: 2021 | K32: 8 | L32: =IF(AND(J32=0,K32=0),"",K32-($B$9-J32)) -> 3 | M32: PROPIO | N32: BUENO | O32: Crítico | P32: NO | Q32: NO APLICA | R32: SI | S32: 2023 | T32: CONTRATO | U32: INNOVAMEDICA | V32: 1057472-9-LQ25 | W32: 130904.37 | X32: 2 | AB32: X | AH32: X | AN32: MP | AT32: MP
A33: HOSPITALIZACIÓN QUIRÚRGICA | B33: PISO 4 | C33: MONITOREO | D33: MEDIANO COSTO | E33: Monitor Signos Vitales | F33: EDAN | G33: X12 | H33: 261594-M21308370037 | I33: 500000010746 | J33: 2021 | K33: 8 | L33: =IF(AND(J33=0,K33=0),"",K33-($B$9-J33)) -> 3 | M33: PROPIO | N33: BUENO | O33: Crítico | P33: NO | Q33: NO APLICA | R33: SI | S33: 2023 | T33: CONTRATO | U33: INNOVAMEDICA | V33: 1057472-9-LQ25 | W33: 130904.37 | X33: 2 | AB33: X | AH33: X | AN33: MP | AT33: MP
A34: MEDICINA | B34: PISO 4 | C34: MONITOREO | D34: MEDIANO COSTO | E34: Monitor Signos Vitales | F34: EDAN | G34: X12 | H34: 261594-M21308370030 | I34: 500000010747 | J34: 2021 | K34: 8 | L34: =IF(AND(J34=0,K34=0),"",K34-($B$9-J34)) -> 3 | M34: PROPIO | N34: BUENO | O34: Crítico | P34: NO | Q34: NO APLICA | R34: SI | S34: 2023 | T34: CONTRATO | U34: INNOVAMEDICA | V34: 1057472-9-LQ25 | W34: 130904.37 | X34: 2 | AB34: X | AH34: X | AN34: MP | AT34: MP
A35: EMERGENCIA ADULTO | B35: PISO 1 | C35: MONITOREO | D35: MEDIANO COSTO | E35: Monitor Signos Vitales | F35: EDAN | G35: X12 | H35: 261594-M21401260085 | I35: 500000010988 | J35: 2022 | K35: 8 | L35: =IF(AND(J35=0,K35=0),"",K35-($B$9-J35)) -> 4 | M35: PROPIO | N35: BUENO | O35: Crítico | P35: NO | Q35: NO APLICA | R35: SI | S35: 2023 | T35: CONTRATO | U35: INNOVAMEDICA | V35: 1057472-9-LQ25 | W35: 130904.37 | X35: 2 | Z35: X | AF35: X | AL35: MP | AR35: MP
A36: EMERGENCIA ADULTO | B36: PISO 1 | C36: MONITOREO | D36: MEDIANO COSTO | E36: Monitor Signos Vitales | F36: EDAN | G36: X12 | H36: 261594-M21401260095 | I36: 500000010995 | J36: 2022 | K36: 8 | L36: =IF(AND(J36=0,K36=0),"",K36-($B$9-J36)) -> 4 | M36: PROPIO | N36: BUENO | O36: Crítico | P36: NO | Q36: NO APLICA | R36: SI | S36: 2023 | T36: CONTRATO | U36: INNOVAMEDICA | V36: 1057472-9-LQ25 | W36: 130904.37 | X36: 2 | Z36: X | AF36: X | AL36: MP | AR36: MP
A37: EMERGENCIA ADULTO | B37: PISO 1 | C37: MONITOREO | D37: MEDIANO COSTO | E37: Monitor Signos Vitales | F37: EDAN | G37: X12 | H37: 261594-M21401260100 | I37: 500000010985 | J37: 2022 | K37: 8 | L37: =IF(AND(J37=0,K37=0),"",K37-($B$9-J37)) -> 4 | M37: PROPIO | N37: BUENO | O37: Crítico | P37: NO | Q37: NO APLICA | R37: SI | S37: 2023 | T37: CONTRATO | U37: INNOVAMEDICA | V37: 1057472-9-LQ25 | W37: 130904.37 | X37: 2 | Z37: X | AF37: X | AL37: MP | AR37: MP
A38: EMERGENCIA ADULTO | B38: PISO 1 | C38: MONITOREO | D38: MEDIANO COSTO | E38: Monitor Signos Vitales | F38: EDAN | G38: X12 | H38: 261594-M21401260098 | I38: 500000010990 | J38: 2022 | K38: 8 | L38: =IF(AND(J38=0,K38=0),"",K38-($B$9-J38)) -> 4 | M38: PROPIO | N38: BUENO | O38: Crítico | P38: NO | Q38: NO APLICA | R38: SI | S38: 2023 | T38: CONTRATO | U38: INNOVAMEDICA | V38: 1057472-9-LQ25 | W38: 130904.37 | X38: 2 | Z38: X | AF38: X | AL38: MP | AR38: MP
A39: EMERGENCIA ADULTO | B39: PISO 1 | C39: MONITOREO | D39: MEDIANO COSTO | E39: Monitor Signos Vitales | F39: EDAN | G39: X12 | H39: 261594-M21401260088 | I39: 500000010996 | J39: 2022 | K39: 8 | L39: =IF(AND(J39=0,K39=0),"",K39-($B$9-J39)) -> 4 | M39: PROPIO | N39: BUENO | O39: Crítico | P39: NO | Q39: NO APLICA | R39: SI | S39: 2023 | T39: CONTRATO | U39: INNOVAMEDICA | V39: 1057472-9-LQ25 | W39: 130904.37 | X39: 2 | Z39: X | AF39: X | AL39: MP | AR39: MP
A40: CENTRO DE ATENCIÓN DE ESPECIALIDADES (CAE) | B40: PISO -1 | C40: MONITOREO | D40: MEDIANO COSTO | E40: Monitor Signos Vitales | F40: EDAN | G40: X12 | H40: 261594-M21401260090 | I40: 500000011000 | J40: 2022 | K40: 8 | L40: =IF(AND(J40=0,K40=0),"",K40-($B$9-J40)) -> 4 | M40: PROPIO | N40: BUENO | O40: Crítico | P40: NO | Q40: NO APLICA | R40: SI | S40: 2023 | T40: CONTRATO | U40: INNOVAMEDICA | V40: 1057472-9-LQ25 | W40: 130904.37 | X40: 2 | Z40: X | AF40: X | AL40: MP | AR40: MP
A41: EMERGENCIA ADULTO | B41: PISO 1 | C41: MONITOREO | D41: MEDIANO COSTO | E41: Monitor Signos Vitales | F41: EDAN | G41: X12 | H41: 261594-M21401260092 | I41: 500000011001 | J41: 2022 | K41: 8 | L41: =IF(AND(J41=0,K41=0),"",K41-($B$9-J41)) -> 4 | M41: PROPIO | N41: BUENO | O41: Crítico | P41: NO | Q41: NO APLICA | R41: SI | S41: 2023 | T41: CONTRATO | U41: INNOVAMEDICA | V41: 1057472-9-LQ25 | W41: 130904.37 | X41: 2 | Z41: X | AF41: X | AL41: MP | AR41: MP
A42: EMERGENCIA ADULTO | B42: PISO 1 | C42: MONITOREO | D42: MEDIANO COSTO | E42: Monitor Signos Vitales | F42: EDAN | G42: X12 | H42: 261594-M21308370027 | I42: 500000010994 | J42: 2022 | K42: 8 | L42: =IF(AND(J42=0,K42=0),"",K42-($B$9-J42)) -> 4 | M42: PROPIO | N42: BUENO | O42: Crítico | P42: NO | Q42: NO APLICA | R42: SI | S42: 2023 | T42: CONTRATO | U42: INNOVAMEDICA | V42: 1057472-9-LQ25 | W42: 130904.37 | X42: 2 | Z42: X | AF42: X | AL42: MP | AR42: MP
...

Sheet SEGUIMIENTO GASTO
B3: SEGUIMIENTO GASTO CONVENIOS DE MANTENIMIENTO
K5: CONTROL MENSUAL EJECUCIÓN
K6: ENERO | M6: FEBRERO | O6: MARZO | Q6: ABRIL | S6: MAYO | U6: JUNIO | W6: JULIO | Y6: AGOSTO | AA6: SEPTIEMBRE | AC6: OCTUBRE | AE6: NOVIEMBRE | AG6: DICIEMBRE
B7: Nº | C7: SERVICIO DE SALUD | D7: ESTABLECIMIENTO | E7: NOMBRE CONVENIO DE MANTENIMIENTO | F7: Nº RESOLUCIÓN / ID / ORDEN DE COMPRA DEL CONVENIO | G7: FECHA RESOLUCIÓN | H7: FECHA DE EXPIRACION CONVENIO | I7: MONTO ANUAL ($) | J7: SUBASIGNACIÓN SIGFE | K7: N° ORDEN DE COMPRA / N° FACTURA | L7: MONTO ($) | M7: N° ORDEN DE COMPRA / N° FACTURA | N7: MONTO ($) | O7: N° ORDEN DE COMPRA / N° FACTURA | P7: MONTO ($) | Q7: N° ORDEN DE COMPRA / N° FACTURA | R7: MONTO ($) | S7: N° ORDEN DE COMPRA / N° FACTURA | T7: MONTO ($) | U7: N° ORDEN DE COMPRA / N° FACTURA | V7: MONTO ($) | W7: N° ORDEN DE COMPRA / N° FACTURA | X7: MONTO ($) | Y7: N° ORDEN DE COMPRA / N° FACTURA | Z7: MONTO ($) | AA7: N° ORDEN DE COMPRA / N° FACTURA | AB7: MONTO ($) | AC7: N° ORDEN DE COMPRA / N° FACTURA | AD7: MONTO ($) | AE7: N° ORDEN DE COMPRA / N° FACTURA | AF7: MONTO ($) | AG7: N° ORDEN DE COMPRA / N° FACTURA | AH7: MONTO ($) | AI7: TOTAL
B8: 1 | C8: METROPOLITANO CENTRAL | D8: HOSPITAL EL CARMEN DR. LUIS VALENTÍN FERRADA | J8: 22.06.006.003 | L8: 0 | N8: 0 | P8: 0 | R8: 0 | T8: 0 | V8: 0 | X8: 0 | Z8: 0 | AB8: 0 | AD8: 0 | AF8: 0 | AH8: 0 | AI8: =+L8+N8+P8+R8+T8+V8+X8+Z8+AB8+AD8+AF8+AH8 -> 0
B9: 2 | C9: METROPOLITANO CENTRAL | D9: HOSPITAL EL CARMEN DR. LUIS VALENTÍN FERRADA | J9: 22.06.006.003 | L9: 0 | N9: 0 | P9: 0 | R9: 0 | T9: 0 | V9: 0 | X9: 0 | Z9: 0 | AB9: 0 | AD9: 0 | AF9: 0 | AH9: 0 | AI9: =+L9+N9+P9+R9+T9+V9+X9+Z9+AB9+AD9+AF9+AH9 -> 0
B10: 3 | C10: METROPOLITANO CENTRAL | D10: HOSPITAL EL CARMEN DR. LUIS VALENTÍN FERRADA | J10: 22.06.006.003 | L10: 0 | N10: 0 | P10: 0 | R10: 0 | T10: 0 | V10: 0 | X10: 0 | Z10: 0 | AB10: 0 | AD10: 0 | AF10: 0 | AH10: 0 | AI10: =+L10+N10+P10+R10+T10+V10+X10+Z10+AB10+AD10+AF10+AH10 -> 0
B11: 4 | C11: METROPOLITANO CENTRAL | D11: HOSPITAL EL CARMEN DR. LUIS VALENTÍN FERRADA | J11: 22.06.006.003 | L11: 0 | N11: 0 | P11: 0 | R11: 0 | T11: 0 | V11: 0 | X11: 0 | Z11: 0 | AB11: 0 | AD11: 0 | AF11: 0 | AH11: 0 | AI11: =+L11+N11+P11+R11+T11+V11+X11+Z11+AB11+AD11+AF11+AH11 -> 0
B12: 5 | C12: METROPOLITANO CENTRAL | D12: HOSPITAL EL CARMEN DR. LUIS VALENTÍN FERRADA | J12: 22.06.006.003 | L12: 0 | N12: 0 | P12: 0 | R12: 0 | T12: 0 | V12: 0 | X12: 0 | Z12: 0 | AB12: 0 | AD12: 0 | AF12: 0 | AH12: 0 | AI12: =+L12+N12+P12+R12+T12+V12+X12+Z12+AB12+AD12+AF12+AH12 -> 0
B13: 6 | C13: METROPOLITANO CENTRAL | D13: HOSPITAL EL CARMEN DR. LUIS VALENTÍN FERRADA | J13: 22.06.006.003 | L13: 0 | N13: 0 | P13: 0 | R13: 0 | T13: 0 | V13: 0 | X13: 0 | Z13: 0 | AB13: 0 | AD13: 0 | AF13: 0 | AH13: 0 | AI13: =+L13+N13+P13+R13+T13+V13+X13+Z13+AB13+AD13+AF13+AH13 -> 0
B14: 7 | C14: METROPOLITANO CENTRAL | D14: HOSPITAL EL CARMEN DR. LUIS VALENTÍN FERRADA | J14: 22.06.006.003 | L14: 0 | N14: 0 | P14: 0 | R14: 0 | T14: 0 | V14: 0 | X14: 0 | Z14: 0 | AB14: 0 | AD14: 0 | AF14: 0 | AH14: 0 | AI14: =+L14+N14+P14+R14+T14+V14+X14+Z14+AB14+AD14+AF14+AH14 -> 0
B15: 8 | C15: METROPOLITANO CENTRAL | D15: HOSPITAL EL CARMEN DR. LUIS VALENTÍN FERRADA | J15: 22.06.006.003 | L15: 0 | N15: 0 | P15: 0 | R15: 0 | T15: 0 | V15: 0 | X15: 0 | Z15: 0 | AB15: 0 | AD15: 0 | AF15: 0 | AH15: 0 | AI15: =+L15+N15+P15+R15+T15+V15+X15+Z15+AB15+AD15+AF15+AH15 -> 0
B16: 9 | C16: METROPOLITANO CENTRAL | D16: HOSPITAL EL CARMEN DR. LUIS VALENTÍN FERRADA | J16: 22.06.006.003 | L16: 0 | N16: 0 | P16: 0 | R16: 0 | T16: 0 | V16: 0 | X16: 0 | Z16: 0 | AB16: 0 | AD16: 0 | AF16: 0 | AH16: 0 | AI16: =+L16+N16+P16+R16+T16+V16+X16+Z16+AB16+AD16+AF16+AH16 -> 0
B17: 10 | C17: METROPOLITANO CENTRAL | D17: HOSPITAL EL CARMEN DR. LUIS VALENTÍN FERRADA | J17: 22.06.006.003 | L17: 0 | N17: 0 | P17: 0 | R17: 0 | T17: 0 | V17: 0 | X17: 0 | Z17: 0 | AB17: 0 | AD17: 0 | AF17: 0 | AH17: 0 | AI17: =+L17+N17+P17+R17+T17+V17+X17+Z17+AB17+AD17+AF17+AH17 -> 0
B18: 11 | C18: METROPOLITANO CENTRAL | D18: HOSPITAL EL CARMEN DR. LUIS VALENTÍN FERRADA | J18: 22.06.006.003 | L18: 0 | N18: 0 | P18: 0 | R18: 0 | T18: 0 | V18: 0 | X18: 0 | Z18: 0 | AB18: 0 | AD18: 0 | AF18: 0 | AH18: 0 | AI18: =+L18+N18+P18+R18+T18+V18+X18+Z18+AB18+AD18+AF18+AH18 -> 0
B19: 12 | C19: METROPOLITANO CENTRAL | D19: HOSPITAL EL CARMEN DR. LUIS VALENTÍN FERRADA | J19: 22.06.006.003 | L19: 0 | N19: 0 | P19: 0 | R19: 0 | T19: 0 | V19: 0 | X19: 0 | Z19: 0 | AB19: 0 | AD19: 0 | AF19: 0 | AH19: 0 | AI19: =+L19+N19+P19+R19+T19+V19+X19+Z19+AB19+AD19+AF19+AH19 -> 0
... B112: 105 | C112: METROPOLITANO CENTRAL | D112: HOSPITAL EL CARMEN DR. LUIS VALENTÍN FERRADA | J112: 22.06.006.003 | L112: 0 | N112: 0 | P112: 0 | R112: 0 | T112: 0 | V112: 0 | X112: 0 | Z112: 0 | AB112: 0 | AD112: 0 | AF112: 0 | AH112: 0 | AI112: =+L112+N112+P112+R112+T112+V112+X112+Z112+AB112+AD112+AF112+AH112 -> 0

Sheet SEGUIMIENTO GASTO CORRECTIVO
B3: SEGUIMIENTO GASTO MANTENIMIENTO CORRECTIVO / ADQUISICIÓN DE REPUESTOS / ADQUISICIÓN DE INSUMOS / ADQUISICIÓN DE ACCESORIOS
I5: CONTROL MENSUAL EJECUCIÓN
I6: ENERO | K6: FEBRERO | M6: MARZO | O6: ABRIL | Q6: MAYO | S6: JUNIO | U6: JULIO | W6: AGOSTO | Y6: SEPTIEMBRE | AA6: OCTUBRE | AC6: NOVIEMBRE | AE6: DICIEMBRE
B7: Nº | C7: SERVICIO DE SALUD | D7: ESTABLECIMIENTO | E7: DESCRIPCIÓN DE LA COMPRA | F7: TIPO DE GASTO CORRECTIVO | G7: MONTO | H7: SUBASIGNACIÓN SIGFE | I7: N° ORDEN DE COMPRA | J7: MONTO ($) | K7: N° ORDEN DE COMPRA | L7: MONTO ($) | M7: N° ORDEN DE COMPRA | N7: MONTO ($) | O7: N° ORDEN DE COMPRA | P7: MONTO ($) | Q7: N° ORDEN DE COMPRA | R7: MONTO ($) | S7: N° ORDEN DE COMPRA | T7: MONTO ($) | U7: N° ORDEN DE COMPRA | V7: MONTO ($) | W7: N° ORDEN DE COMPRA | X7: MONTO ($) | Y7: N° ORDEN DE COMPRA | Z7: MONTO ($) | AA7: N° ORDEN DE COMPRA | AB7: MONTO ($) | AC7: N° ORDEN DE COMPRA | AD7: MONTO ($) | AE7: N° ORDEN DE COMPRA | AF7: MONTO ($) | AG7: TOTAL
B8: 1 | C8: METROPOLITANO CENTRAL | D8: HOSPITAL EL CARMEN DR. LUIS VALENTÍN FERRADA | F8: MANTENIMIENTO CORRECTIVO | H8: 22.06.006.004 | J8: 0 | L8: 0 | N8: 0 | P8: 0 | R8: 0 | T8: 0 | V8: 0 | X8: 0 | Z8: 0 | AB8: 0 | AD8: 0 | AF8: 0 | AG8: =+J8+L8+N8+P8+R8+T8+V8+X8+Z8+AB8+AD8+AF8 -> 0
B9: 2 | C9: METROPOLITANO CENTRAL | D9: HOSPITAL EL CARMEN DR. LUIS VALENTÍN FERRADA | F9: MANTENIMIENTO CORRECTIVO | H9: 22.06.006.004 | J9: 0 | L9: 0 | N9: 0 | P9: 0 | R9: 0 | T9: 0 | V9: 0 | X9: 0 | Z9: 0 | AB9: 0 | AD9: 0 | AF9: 0 | AG9: =+J9+L9+N9+P9+R9+T9+V9+X9+Z9+AB9+AD9+AF9 -> 0
B10: 3 | C10: METROPOLITANO CENTRAL | D10: HOSPITAL EL CARMEN DR. LUIS VALENTÍN FERRADA | F10: MANTENIMIENTO CORRECTIVO | H10: 22.06.006.004 | J10: 0 | L10: 0 | N10: 0 | P10: 0 | R10: 0 | T10: 0 | V10: 0 | X10: 0 | Z10: 0 | AB10: 0 | AD10: 0 | AF10: 0 | AG10: =+J10+L10+N10+P10+R10+T10+V10+X10+Z10+AB10+AD10+AF10 -> 0
B11: 4 | C11: METROPOLITANO CENTRAL | D11: HOSPITAL EL CARMEN DR. LUIS VALENTÍN FERRADA | F11: MANTENIMIENTO CORRECTIVO | H11: 22.06.006.004 | J11: 0 | L11: 0 | N11: 0 | P11: 0 | R11: 0 | T11: 0 | V11: 0 | X11: 0 | Z11: 0 | AB11: 0 | AD11: 0 | AF11: 0 | AG11: =+J11+L11+N11+P11+R11+T11+V11+X11+Z11+AB11+AD11+AF11 -> 0
B12: 5 | C12: METROPOLITANO CENTRAL | D12: HOSPITAL EL CARMEN DR. LUIS VALENTÍN FERRADA | F12: MANTENIMIENTO CORRECTIVO | H12: 22.06.006.004 | J12: 0 | L12: 0 | N12: 0 | P12: 0 | R12: 0 | T12: 0 | V12: 0 | X12: 0 | Z12: 0 | AB12: 0 | AD12: 0 | AF12: 0 | AG12: =+J12+L12+N12+P12+R12+T12+V12+X12+Z12+AB12+AD12+AF12 -> 0
B13: 6 | C13: METROPOLITANO CENTRAL | D13: HOSPITAL EL CARMEN DR. LUIS VALENTÍN FERRADA | F13: MANTENIMIENTO CORRECTIVO | H13: 22.06.006.004 | J13: 0 | L13: 0 | N13: 0 | P13: 0 | R13: 0 | T13: 0 | V13: 0 | X13: 0 | Z13: 0 | AB13: 0 | AD13: 0 | AF13: 0 | AG13: =+J13+L13+N13+P13+R13+T13+V13+X13+Z13+AB13+AD13+AF13 -> 0
B14: 7 | C14: METROPOLITANO CENTRAL | D14: HOSPITAL EL CARMEN DR. LUIS VALENTÍN FERRADA | F14: MANTENIMIENTO CORRECTIVO | H14: 22.06.006.004 | J14: 0 | L14: 0 | N14: 0 | P14: 0 | R14: 0 | T14: 0 | V14: 0 | X14: 0 | Z14: 0 | AB14: 0 | AD14: 0 | AF14: 0 | AG14: =+J14+L14+N14+P14+R14+T14+V14+X14+Z14+AB14+AD14+AF14 -> 0
B15: 8 | C15: METROPOLITANO CENTRAL | D15: HOSPITAL EL CARMEN DR. LUIS VALENTÍN FERRADA | F15: MANTENIMIENTO CORRECTIVO | H15: 22.06.006.004 | J15: 0 | L15: 0 | N15: 0 | P15: 0 | R15: 0 | T15: 0 | V15: 0 | X15: 0 | Z15: 0 | AB15: 0 | AD15: 0 | AF15: 0 | AG15: =+J15+L15+N15+P15+R15+T15+V15+X15+Z15+AB15+AD15+AF15 -> 0
B16: 9 | C16: METROPOLITANO CENTRAL | D16: HOSPITAL EL CARMEN DR. LUIS VALENTÍN FERRADA | F16: MANTENIMIENTO CORRECTIVO | H16: 22.06.006.004 | J16: 0 | L16: 0 | N16: 0 | P16: 0 | R16: 0 | T16: 0 | V16: 0 | X16: 0 | Z16: 0 | AB16: 0 | AD16: 0 | AF16: 0 | AG16: =+J16+L16+N16+P16+R16+T16+V16+X16+Z16+AB16+AD16+AF16 -> 0
B17: 10 | C17: METROPOLITANO CENTRAL | D17: HOSPITAL EL CARMEN DR. LUIS VALENTÍN FERRADA | F17: MANTENIMIENTO CORRECTIVO | H17: 22.06.006.004 | J17: 0 | L17: 0 | N17: 0 | P17: 0 | R17: 0 | T17: 0 | V17: 0 | X17: 0 | Z17: 0 | AB17: 0 | AD17: 0 | AF17: 0 | AG17: =+J17+L17+N17+P17+R17+T17+V17+X17+Z17+AB17+AD17+AF17 -> 0
B18: 11 | C18: METROPOLITANO CENTRAL | D18: HOSPITAL EL CARMEN DR. LUIS VALENTÍN FERRADA | F18: MANTENIMIENTO CORRECTIVO | H18: 22.06.006.004 | J18: 0 | L18: 0 | N18: 0 | P18: 0 | R18: 0 | T18: 0 | V18: 0 | X18: 0 | Z18: 0 | AB18: 0 | AD18: 0 | AF18: 0 | AG18: =+J18+L18+N18+P18+R18+T18+V18+X18+Z18+AB18+AD18+AF18 -> 0
B19: 12 | C19: METROPOLITANO CENTRAL | D19: HOSPITAL EL CARMEN DR. LUIS VALENTÍN FERRADA | F19: MANTENIMIENTO CORRECTIVO | H19: 22.06.006.004 | J19: 0 | L19: 0 | N19: 0 | P19: 0 | R19: 0 | T19: 0 | V19: 0 | X19: 0 | Z19: 0 | AB19: 0 | AD19: 0 | AF19: 0 | AG19: =+J19+L19+N19+P19+R19+T19+V19+X19+Z19+AB19+AD19+AF19 -> 0
... B224: 217 | C224: METROPOLITANO CENTRAL | D224: HOSPITAL EL CARMEN DR. LUIS VALENTÍN FERRADA | F224: MANTENIMIENTO CORRECTIVO | H224: 22.06.006.004 | J224: 0 | L224: 0 | N224: 0 | P224: 0 | R224: 0 | T224: 0 | V224: 0 | X224: 0 | Z224: 0 | AB224: 0 | AD224: 0 | AF224: 0 | AG224: =+J224+L224+N224+P224+R224+T224+V224+X224+Z224+AB224+AD224+AF224 -> 0
B225: 218 | C225: METROPOLITANO CENTRAL | D225: HOSPITAL EL CARMEN DR. LUIS VALENTÍN FERRADA | F225: MANTENIMIENTO CORRECTIVO | G225: 0 | H225: 22.06.006.004 | J225: 0 | L225: 0 | N225: 0 | P225: 0 | R225: 0 | T225: 0 | V225: 0 | X225: 0 | Z225: 0 | AB225: 0 | AD225: 0 | AF225: 0 | AG225: =+J225+L225+N225+P225+R225+T225+V225+X225+Z225+AB225+AD225+AF225 -> 0
B226: 219 | C226: METROPOLITANO CENTRAL | D226: HOSPITAL EL CARMEN DR. LUIS VALENTÍN FERRADA | F226: MANTENIMIENTO CORRECTIVO | G226: 0 | H226: 22.06.006.004 | J226: 0 | L226: 0 | N226: 0 | P226: 0 | R226: 0 | T226: 0 | V226: 0 | X226: 0 | Z226: 0 | AB226: 0 | AD226: 0 | AF226: 0 | AG226: =+J226+L226+N226+P226+R226+T226+V226+X226+Z226+AB226+AD226+AF226 -> 0
B227: 220 | C227: METROPOLITANO CENTRAL | D227: HOSPITAL EL CARMEN DR. LUIS VALENTÍN FERRADA | F227: MANTENIMIENTO CORRECTIVO | G227: 0 | H227: 22.06.006.004 | J227: 0 | L227: 0 | N227: 0 | P227: 0 | R227: 0 | T227: 0 | V227: 0 | X227: 0 | Z227: 0 | AB227: 0 | AD227: 0 | AF227: 0 | AG227: =+J227+L227+N227+P227+R227+T227+V227+X227+Z227+AB227+AD227+AF227 -> 0
B228: 221 | C228: METROPOLITANO CENTRAL | D228: HOSPITAL EL CARMEN DR. LUIS VALENTÍN FERRADA | F228: MANTENIMIENTO CORRECTIVO | G228: 0 | H228: 22.06.006.004 | J228: 0 | L228: 0 | N228: 0 | P228: 0 | R228: 0 | T228: 0 | V228: 0 | X228: 0 | Z228: 0 | AB228: 0 | AD228: 0 | AF228: 0 | AG228: =+J228+L228+N228+P228+R228+T228+V228+X228+Z228+AB228+AD228+AF228 -> 0
B229: 222 | C229: METROPOLITANO CENTRAL | D229: HOSPITAL EL CARMEN DR. LUIS VALENTÍN FERRADA | F229: MANTENIMIENTO CORRECTIVO | G229: 0 | H229: 22.06.006.004 | J229: 0 | L229: 0 | N229: 0 | P229: 0 | R229: 0 | T229: 0 | V229: 0 | X229: 0 | Z229: 0 | AB229: 0 | AD229: 0 | AF229: 0 | AG229: =+J229+L229+N229+P229+R229+T229+V229+X229+Z229+AB229+AD229+AF229 -> 0
B230: 223 | C230: METROPOLITANO CENTRAL | D230: HOSPITAL EL CARMEN DR. LUIS VALENTÍN FERRADA | F230: MANTENIMIENTO CORRECTIVO | G230: 0 | H230: 22.06.006.004 | J230: 0 | L230: 0 | N230: 0 | P230: 0 | R230: 0 | T230: 0 | V230: 0 | X230: 0 | Z230: 0 | AB230: 0 | AD230: 0 | AF230: 0 | AG230: =+J230+L230+N230+P230+R230+T230+V230+X230+Z230+AB230+AD230+AF230 -> 0
B231: 224 | C231: METROPOLITANO CENTRAL | D231: HOSPITAL EL CARMEN DR. LUIS VALENTÍN FERRADA | F231: MANTENIMIENTO CORRECTIVO | G231: 0 | H231: 22.06.006.004 | J231: 0 | L231: 0 | N231: 0 | P231: 0 | R231: 0 | T231: 0 | V231: 0 | X231: 0 | Z231: 0 | AB231: 0 | AD231: 0 | AF231: 0 | AG231: =+J231+L231+N231+P231+R231+T231+V231+X231+Z231+AB231+AD231+AF231 -> 0
B232: 225 | C232: METROPOLITANO CENTRAL | D232: HOSPITAL EL CARMEN DR. LUIS VALENTÍN FERRADA | F232: MANTENIMIENTO CORRECTIVO | G232: 0 | H232: 22.06.006.004 | J232: 0 | L232: 0 | N232: 0 | P232: 0 | R232: 0 | T232: 0 | V232: 0 | X232: 0 | Z232: 0 | AB232: 0 | AD232: 0 | AF232: 0 | AG232: =+J232+L232+N232+P232+R232+T232+V232+X232+Z232+AB232+AD232+AF232 -> 0
B233: 226 | C233: METROPOLITANO CENTRAL | D233: HOSPITAL EL CARMEN DR. LUIS VALENTÍN FERRADA | F233: MANTENIMIENTO CORRECTIVO | G233: 0 | H233: 22.06.006.004 | J233: 0 | L233: 0 | N233: 0 | P233: 0 | R233: 0 | T233: 0 | V233: 0 | X233: 0 | Z233: 0 | AB233: 0 | AD233: 0 | AF233: 0 | AG233: =+J233+L233+N233+P233+R233+T233+V233+X233+Z233+AB233+AD233+AF233 -> 0
B234: 227 | C234: METROPOLITANO CENTRAL | D234: HOSPITAL EL CARMEN DR. LUIS VALENTÍN FERRADA | F234: MANTENIMIENTO CORRECTIVO | G234: 0 | H234: 22.06.006.004 | J234: 0 | L234: 0 | N234: 0 | P234: 0 | R234: 0 | T234: 0 | V234: 0 | X234: 0 | Z234: 0 | AB234: 0 | AD234: 0 | AF234: 0 | AG234: =+J234+L234+N234+P234+R234+T234+V234+X234+Z234+AB234+AD234+AF234 -> 0
B235: 228 | C235: METROPOLITANO CENTRAL | D235: HOSPITAL EL CARMEN DR. LUIS VALENTÍN FERRADA | F235: MANTENIMIENTO CORRECTIVO | G235: 0 | H235: 22.06.006.004 | J235: 0 | L235: 0 | N235: 0 | P235: 0 | R235: 0 | T235: 0 | V235: 0 | X235: 0 | Z235: 0 | AB235: 0 | AD235: 0 | AF235: 0 | AG235: =+J235+L235+N235+P235+R235+T235+V235+X235+Z235+AB235+AD235+AF235 -> 0
B236: 229 | C236: METROPOLITANO CENTRAL | D236: HOSPITAL EL CARMEN DR. LUIS VALENTÍN FERRADA | F236: MANTENIMIENTO CORRECTIVO | G236: 0 | H236: 22.06.006.004 | J236: 0 | L236: 0 | N236: 0 | P236: 0 | R236: 0 | T236: 0 | V236: 0 | X236: 0 | Z236: 0 | AB236: 0 | AD236: 0 | AF236: 0 | AG236: =+J236+L236+N236+P236+R236+T236+V236+X236+Z236+AB236+AD236+AF236 -> 0
... B304: 297 | C304: METROPOLITANO CENTRAL | D304: HOSPITAL EL CARMEN DR. LUIS VALENTÍN FERRADA | F304: MANTENIMIENTO CORRECTIVO | G304: 0 | H304: 22.06.006.004 | J304: 0 | L304: 0 | N304: 0 | P304: 0 | R304: 0 | T304: 0 | V304: 0 | X304: 0 | Z304: 0 | AB304: 0 | AD304: 0 | AF304: 0 | AG304: =+J304+L304+N304+P304+R304+T304+V304+X304+Z304+AB304+AD304+AF304 -> 0

Sheet TABLA CÁLCULO
A3: Etiquetas de fila | B3: Suma de FRECUENCIA ANUAL DE MANTENIMIENTO
A4: CRÍTICO | B4: 6
A5: IM ≥ 12 | B5: 6
A6: RELEVANTE | B6: 3
A7: (en blanco)
A8: Total general | B8: 15
A12: N° MP PROGRAMADAS | O12: TOTAL MP PROGRAMADAS | P12: =+GETPIVOTDATA("FRECUENCIA ANUAL DE MANTENIMIENTO",$A$49,"AÑO INGRESO A PLAN DE MANTENIMIENTO (2023 / 2024 / 2025 / 2026)",2023) -> 10
A13: N° MP EJECUTADAS | B13: =+COUNTIF('CATASTRO Y PLANIFICACIÓN MP'!Y16:Y2620,"√") -> 0 | C13: =+COUNTIF('CATASTRO Y PLANIFICACIÓN MP'!Z16:Z2620,"√") -> 0 | D13: =+COUNTIF('CATASTRO Y PLANIFICACIÓN MP'!AA16:AA2620,"√") -> 0 | E13: =+COUNTIF('CATASTRO Y PLANIFICACIÓN MP'!AB16:AB2620,"√") -> 0 | F13: =+COUNTIF('CATASTRO Y PLANIFICACIÓN MP'!AC16:AC2620,"√") -> 0 | G13: =+COUNTIF('CATASTRO Y PLANIFICACIÓN MP'!AD16:AD2620,"√") -> 0 | H13: =+COUNTIF('CATASTRO Y PLANIFICACIÓN MP'!AE16:AE2620,"√") -> 0 | I13: =+COUNTIF('CATASTRO Y PLANIFICACIÓN MP'!AF16:AF2620,"√") -> 0 | ... M13: =+COUNTIF('CATASTRO Y PLANIFICACIÓN MP'!AJ16:AJ2620,"√") -> 0 | O13: TOTAL MP EJECUTADAS | P13: =+SUM(B13:M13) -> 0 | R13: X | S13: PROGRAMADO | U13: CRÍTICO | W13: SI | Y13: 2023 | AA13: INTERNO | AC13: 1 | AE13: PROPIO | AF13: BUENO
A14: N° MP REPROGRAMADAS | B14: =+COUNTIF('CATASTRO Y PLANIFICACIÓN MP'!Y16:Y2620,"ꓣ") -> 0 | C14: =+COUNTIF('CATASTRO Y PLANIFICACIÓN MP'!Z16:Z2620,"ꓣ") -> 0 | D14: =+COUNTIF('CATASTRO Y PLANIFICACIÓN MP'!AA16:AA2620,"ꓣ") -> 0 | E14: =+COUNTIF('CATASTRO Y PLANIFICACIÓN MP'!AB16:AB2620,"ꓣ") -> 0 | F14: =+COUNTIF('CATASTRO Y PLANIFICACIÓN MP'!AC16:AC2620,"ꓣ") -> 0 | G14: =+COUNTIF('CATASTRO Y PLANIFICACIÓN MP'!AD16:AD2620,"ꓣ") -> 0 | H14: =+COUNTIF('CATASTRO Y PLANIFICACIÓN MP'!AE16:AE2620,"ꓣ") -> 0 | I14: =+COUNTIF('CATASTRO Y PLANIFICACIÓN MP'!AF16:AF2620,"ꓣ") -> 0 | ... M14: =+COUNTIF('CATASTRO Y PLANIFICACIÓN MP'!AJ16:AJ2620,"ꓣ") -> 0 | O14: TOTAL MP REPROGRAMADAS | P14: =+SUM(B14:M14) -> 0 | R14: √ | S14: REALIZADO | U14: RELEVANTE | W14: NO | Y14: 2024 | AA14: EXTERNO | AC14: 2 | AE14: ARRIENDO | AF14: REGULAR
O15: TOTAL MP PROGRAMADAS EQC | P15: =+GETPIVOTDATA("FRECUENCIA ANUAL DE MANTENIMIENTO",$A$49,"CRÍTICO/ RELEVANTE / IM≥12 / NO APLICA","CRÍTICO","AÑO INGRESO A PLAN DE MANTENIMIENTO (2023 / 2024 / 2025 / 2026)",2023) -> 6 | R15: ꓣ | S15: REPROGRAMADO | U15: IM ≥ 12 | Y15: 2025 | AA15: CONTRATO | AC15: 3 | AE15: COMODATO | AF15: MALO
A16: N° MP EJECUTADAS EQC | B16: =+COUNTIFS('CATASTRO Y PLANIFICACIÓN MP'!$O$16:$O$2620,"CRÍTICO",'CATASTRO Y PLANIFICACIÓN MP'!Y16:Y2620,"√") -> 0 | C16: =+COUNTIFS('CATASTRO Y PLANIFICACIÓN MP'!$O$16:$O$2620,"CRÍTICO",'CATASTRO Y PLANIFICACIÓN MP'!Z16:Z2620,"√") -> 0 | D16: =+COUNTIFS('CATASTRO Y PLANIFICACIÓN MP'!$O$16:$O$2620,"CRÍTICO",'CATASTRO Y PLANIFICACIÓN MP'!AA16:AA2620,"√") -> 0 | E16: =+COUNTIFS('CATASTRO Y PLANIFICACIÓN MP'!$O$16:$O$2620,"CRÍTICO",'CATASTRO Y PLANIFICACIÓN MP'!AB16:AB2620,"√") -> 0 | F16: =+COUNTIFS('CATASTRO Y PLANIFICACIÓN MP'!$O$16:$O$2620,"CRÍTICO",'CATASTRO Y PLANIFICACIÓN MP'!AC16:AC2620,"√") -> 0 | G16: =+COUNTIFS('CATASTRO Y PLANIFICACIÓN MP'!$O$16:$O$2620,"CRÍTICO",'CATASTRO Y PLANIFICACIÓN MP'!AD16:AD2620,"√") -> 0 | H16: =+COUNTIFS('CATASTRO Y PLANIFICACIÓN MP'!$O$16:$O$2620,"CRÍTICO",'CATASTRO Y PLANIFICACIÓN MP'!AE16:AE2620,"√") -> 0 | I16: =+COUNTIFS('CATASTRO Y PLANIFICACIÓN MP'!$O$16:$O$2620,"CRÍTICO",'CATASTRO Y PLANIFICACIÓN MP'!AF16:AF2620,"√") -> 0 | ... M16: =+COUNTIFS('CATASTRO Y PLANIFICACIÓN MP'!$O$16:$O$2620,"CRÍTICO",'CATASTRO Y PLANIFICACIÓN MP'!AJ16:AJ2620,"√") -> 0 | O16: TOTAL MP PROGRAMADAS EQR | P16: =+GETPIVOTDATA("FRECUENCIA ANUAL DE MANTENIMIENTO",$A$49,"CRÍTICO/ RELEVANTE / IM≥12 / NO APLICA","RELEVANTE","AÑO INGRESO A PLAN DE MANTENIMIENTO (2023 / 2024 / 2025 / 2026)",2023) -> 1 | U16: NO APLICA | Y16: 2026 | AC16: 4 | AE16: PRÉSTAMO | AF16: BAJA, PARA REPOSICIÓN
A17: N° MP EJECUTADAS EQR | B17: =+COUNTIFS('CATASTRO Y PLANIFICACIÓN MP'!$O$16:$O$2620,"RELEVANTE",'CATASTRO Y PLANIFICACIÓN MP'!Y16:Y2620,"√") -> 0 | C17: =+COUNTIFS('CATASTRO Y PLANIFICACIÓN MP'!$O$16:$O$2620,"RELEVANTE",'CATASTRO Y PLANIFICACIÓN MP'!Z16:Z2620,"√") -> 0 | D17: =+COUNTIFS('CATASTRO Y PLANIFICACIÓN MP'!$O$16:$O$2620,"RELEVANTE",'CATASTRO Y PLANIFICACIÓN MP'!AA16:AA2620,"√") -> 0 | E17: =+COUNTIFS('CATASTRO Y PLANIFICACIÓN MP'!$O$16:$O$2620,"RELEVANTE",'CATASTRO Y PLANIFICACIÓN MP'!AB16:AB2620,"√") -> 0 | F17: =+COUNTIFS('CATASTRO Y PLANIFICACIÓN MP'!$O$16:$O$2620,"RELEVANTE",'CATASTRO Y PLANIFICACIÓN MP'!AC16:AC2620,"√") -> 0 | G17: =+COUNTIFS('CATASTRO Y PLANIFICACIÓN MP'!$O$16:$O$2620,"RELEVANTE",'CATASTRO Y PLANIFICACIÓN MP'!AD16:AD2620,"√") -> 0 | H17: =+COUNTIFS('CATASTRO Y PLANIFICACIÓN MP'!$O$16:$O$2620,"RELEVANTE",'CATASTRO Y PLANIFICACIÓN MP'!AE16:AE2620,"√") -> 0 | I17: =+COUNTIFS('CATASTRO Y PLANIFICACIÓN MP'!$O$16:$O$2620,"RELEVANTE",'CATASTRO Y PLANIFICACIÓN MP'!AF16:AF2620,"√") -> 0 | ... M17: =+COUNTIFS('CATASTRO Y PLANIFICACIÓN MP'!$O$16:$O$2620,"RELEVANTE",'CATASTRO Y PLANIFICACIÓN MP'!AJ16:AJ2620,"√") -> 0 | O17: TOTAL MP PROGRAMADAS IM≥12 | P17: =+GETPIVOTDATA("FRECUENCIA ANUAL DE MANTENIMIENTO",$A$49,"CRÍTICO/ RELEVANTE / IM≥12 / NO APLICA","IM ≥ 12","AÑO INGRESO A PLAN DE MANTENIMIENTO (2023 / 2024 / 2025 / 2026)",2023) -> 3 | AC17: 6
A18: N° MP EJECUTADAS IM≥12 | B18: =+COUNTIFS('CATASTRO Y PLANIFICACIÓN MP'!$O$16:$O$2620,"IM ≥ 12",'CATASTRO Y PLANIFICACIÓN MP'!Y16:Y2620,"√") -> 0 | C18: =+COUNTIFS('CATASTRO Y PLANIFICACIÓN MP'!$O$16:$O$2620,"IM ≥ 12",'CATASTRO Y PLANIFICACIÓN MP'!Z16:Z2620,"√") -> 0 | D18: =+COUNTIFS('CATASTRO Y PLANIFICACIÓN MP'!$O$16:$O$2620,"IM ≥ 12",'CATASTRO Y PLANIFICACIÓN MP'!AA16:AA2620,"√") -> 0 | E18: =+COUNTIFS('CATASTRO Y PLANIFICACIÓN MP'!$O$16:$O$2620,"IM ≥ 12",'CATASTRO Y PLANIFICACIÓN MP'!AB16:AB2620,"√") -> 0 | F18: =+COUNTIFS('CATASTRO Y PLANIFICACIÓN MP'!$O$16:$O$2620,"IM ≥ 12",'CATASTRO Y PLANIFICACIÓN MP'!AC16:AC2620,"√") -> 0 | G18: =+COUNTIFS('CATASTRO Y PLANIFICACIÓN MP'!$O$16:$O$2620,"IM ≥ 12",'CATASTRO Y PLANIFICACIÓN MP'!AD16:AD2620,"√") -> 0 | H18: =+COUNTIFS('CATASTRO Y PLANIFICACIÓN MP'!$O$16:$O$2620,"IM ≥ 12",'CATASTRO Y PLANIFICACIÓN MP'!AE16:AE2620,"√") -> 0 | I18: =+COUNTIFS('CATASTRO Y PLANIFICACIÓN MP'!$O$16:$O$2620,"IM ≥ 12",'CATASTRO Y PLANIFICACIÓN MP'!AF16:AF2620,"√") -> 0 | ... M18: =+COUNTIFS('CATASTRO Y PLANIFICACIÓN MP'!$O$16:$O$2620,"IM ≥ 12",'CATASTRO Y PLANIFICACIÓN MP'!AJ16:AJ2620,"√") -> 0 | O18: TOTAL MP EJECUTADAS EQC | P18: =+SUM(B16:M16) -> 0 | AC18: 12
A19: N° MP REPROGRAMADAS EQC | B19: =+COUNTIFS('CATASTRO Y PLANIFICACIÓN MP'!$O$16:$O$2620,"CRÍTICO",'CATASTRO Y PLANIFICACIÓN MP'!Y16:Y2620,"ꓣ") -> 0 | C19: =+COUNTIFS('CATASTRO Y PLANIFICACIÓN MP'!$O$16:$O$2620,"CRÍTICO",'CATASTRO Y PLANIFICACIÓN MP'!Z16:Z2620,"ꓣ") -> 0 | D19: =+COUNTIFS('CATASTRO Y PLANIFICACIÓN MP'!$O$16:$O$2620,"CRÍTICO",'CATASTRO Y PLANIFICACIÓN MP'!AA16:AA2620,"ꓣ") -> 0 | E19: =+COUNTIFS('CATASTRO Y PLANIFICACIÓN MP'!$O$16:$O$2620,"CRÍTICO",'CATASTRO Y PLANIFICACIÓN MP'!AB16:AB2620,"ꓣ") -> 0 | F19: =+COUNTIFS('CATASTRO Y PLANIFICACIÓN MP'!$O$16:$O$2620,"CRÍTICO",'CATASTRO Y PLANIFICACIÓN MP'!AC16:AC2620,"ꓣ") -> 0 | G19: =+COUNTIFS('CATASTRO Y PLANIFICACIÓN MP'!$O$16:$O$2620,"CRÍTICO",'CATASTRO Y PLANIFICACIÓN MP'!AD16:AD2620,"ꓣ") -> 0 | H19: =+COUNTIFS('CATASTRO Y PLANIFICACIÓN MP'!$O$16:$O$2620,"CRÍTICO",'CATASTRO Y PLANIFICACIÓN MP'!AE16:AE2620,"ꓣ") -> 0 | I19: =+COUNTIFS('CATASTRO Y PLANIFICACIÓN MP'!$O$16:$O$2620,"CRÍTICO",'CATASTRO Y PLANIFICACIÓN MP'!AF16:AF2620,"ꓣ") -> 0 | ... M19: =+COUNTIFS('CATASTRO Y PLANIFICACIÓN MP'!$O$16:$O$2620,"CRÍTICO",'CATASTRO Y PLANIFICACIÓN MP'!AJ16:AJ2620,"ꓣ") -> 0 | O19: TOTAL MP EJECUTADAS EQR | P19: =+SUM(B17:M17) -> 0 | S19: MANTENIMIENTO CORRECTIVO
A20: N° MP REPROGRAMADAS EQR | B20: =+COUNTIFS('CATASTRO Y PLANIFICACIÓN MP'!$O$16:$O$2620,"RELEVANTE",'CATASTRO Y PLANIFICACIÓN MP'!Y16:Y2620,"ꓣ") -> 0 | C20: =+COUNTIFS('CATASTRO Y PLANIFICACIÓN MP'!$O$16:$O$2620,"RELEVANTE",'CATASTRO Y PLANIFICACIÓN MP'!Z16:Z2620,"ꓣ") -> 0 | D20: =+COUNTIFS('CATASTRO Y PLANIFICACIÓN MP'!$O$16:$O$2620,"RELEVANTE",'CATASTRO Y PLANIFICACIÓN MP'!AA16:AA2620,"ꓣ") -> 0 | E20: =+COUNTIFS('CATASTRO Y PLANIFICACIÓN MP'!$O$16:$O$2620,"RELEVANTE",'CATASTRO Y PLANIFICACIÓN MP'!AB16:AB2620,"ꓣ") -> 0 | F20: =+COUNTIFS('CATASTRO Y PLANIFICACIÓN MP'!$O$16:$O$2620,"RELEVANTE",'CATASTRO Y PLANIFICACIÓN MP'!AC16:AC2620,"ꓣ") -> 0 | G20: =+COUNTIFS('CATASTRO Y PLANIFICACIÓN MP'!$O$16:$O$2620,"RELEVANTE",'CATASTRO Y PLANIFICACIÓN MP'!AD16:AD2620,"ꓣ") -> 0 | H20: =+COUNTIFS('CATASTRO Y PLANIFICACIÓN MP'!$O$16:$O$2620,"RELEVANTE",'CATASTRO Y PLANIFICACIÓN MP'!AE16:AE2620,"ꓣ") -> 0 | I20: =+COUNTIFS('CATASTRO Y PLANIFICACIÓN MP'!$O$16:$O$2620,"RELEVANTE",'CATASTRO Y PLANIFICACIÓN MP'!AF16:AF2620,"ꓣ") -> 0 | ... M20: =+COUNTIFS('CATASTRO Y PLANIFICACIÓN MP'!$O$16:$O$2620,"RELEVANTE",'CATASTRO Y PLANIFICACIÓN MP'!AJ16:AJ2620,"ꓣ") -> 0 | O20: TOTAL MP EJECUTADAS IM≥12 | P20: =+SUM(B18:M18) -> 0 | S20: ADQUISICIÓN DE REPUESTOS
A21: N° MP REPROGRAMADAS IM≥12 | B21: =+COUNTIFS('CATASTRO Y PLANIFICACIÓN MP'!$O$16:$O$2620,"IM ≥ 12",'CATASTRO Y PLANIFICACIÓN MP'!Y16:Y2620,"ꓣ") -> 0 | C21: =+COUNTIFS('CATASTRO Y PLANIFICACIÓN MP'!$O$16:$O$2620,"IM ≥ 12",'CATASTRO Y PLANIFICACIÓN MP'!Z16:Z2620,"ꓣ") -> 0 | D21: =+COUNTIFS('CATASTRO Y PLANIFICACIÓN MP'!$O$16:$O$2620,"IM ≥ 12",'CATASTRO Y PLANIFICACIÓN MP'!AA16:AA2620,"ꓣ") -> 0 | E21: =+COUNTIFS('CATASTRO Y PLANIFICACIÓN MP'!$O$16:$O$2620,"IM ≥ 12",'CATASTRO Y PLANIFICACIÓN MP'!AB16:AB2620,"ꓣ") -> 0 | F21: =+COUNTIFS('CATASTRO Y PLANIFICACIÓN MP'!$O$16:$O$2620,"IM ≥ 12",'CATASTRO Y PLANIFICACIÓN MP'!AC16:AC2620,"ꓣ") -> 0 | G21: =+COUNTIFS('CATASTRO Y PLANIFICACIÓN MP'!$O$16:$O$2620,"IM ≥ 12",'CATASTRO Y PLANIFICACIÓN MP'!AD16:AD2620,"ꓣ") -> 0 | H21: =+COUNTIFS('CATASTRO Y PLANIFICACIÓN MP'!$O$16:$O$2620,"IM ≥ 12",'CATASTRO Y PLANIFICACIÓN MP'!AE16:AE2620,"ꓣ") -> 0 | I21: =+COUNTIFS('CATASTRO Y PLANIFICACIÓN MP'!$O$16:$O$2620,"IM ≥ 12",'CATASTRO Y PLANIFICACIÓN MP'!AF16:AF2620,"ꓣ") -> 0 | ... M21: =+COUNTIFS('CATASTRO Y PLANIFICACIÓN MP'!$O$16:$O$2620,"IM ≥ 12",'CATASTRO Y PLANIFICACIÓN MP'!AJ16:AJ2620,"ꓣ") -> 0 | S21: ADQUISICIÓN DE INSUMOS
O22: INDICADOR | P22: NIVEL ALCANZADO | S22: ADQUISICION DE ACCESORIOS
O23: % EJECUCION ANUAL MP | P23: =+P13/P12 -> 0 | S23: OTRO
A24: % EJECUCIÓN MP TOTAL MENSUAL | B24: =+IFERROR(B13/(B13+B14),"") | C24: =+IFERROR(C13/(C13+C14),"") | D24: =+IFERROR(D13/(D13+D14),"") | E24: =+IFERROR(E13/(E13+E14),"") | F24: =+IFERROR(F13/(F13+F14),"") | G24: =+IFERROR(G13/(G13+G14),"") | H24: =+IFERROR(H13/(H13+H14),"") | I24: =+IFERROR(I13/(I13+I14),"") | ... M24: =+IFERROR(M13/(M13+M14),"") | O24: % EJECUCIÓN ANUAL EQC | P24: =+P18/P15 -> 0
A25: % EJECUCIÓN MP EQC MENSUAL | B25: =+IFERROR(B16/(B16+B19),"") | C25: =+IFERROR(C16/(C16+C19),"") | D25: =+IFERROR(D16/(D16+D19),"") | E25: =+IFERROR(E16/(E16+E19),"") | F25: =+IFERROR(F16/(F16+F19),"") | G25: =+IFERROR(G16/(G16+G19),"") | H25: =+IFERROR(H16/(H16+H19),"") | I25: =+IFERROR(I16/(I16+I19),"") | ... M25: =+IFERROR(M16/(M16+M19),"") | O25: % EJECUCIÓN ANUAL EQR | P25: =+P19/P16 -> 0
A26: % EJECUCIÓN MP EQR MENSUAL | B26: =+IFERROR(B17/(B17+B20),"") | C26: =+IFERROR(C17/(C17+C20),"") | D26: =+IFERROR(D17/(D17+D20),"") | E26: =+IFERROR(E17/(E17+E20),"") | F26: =+IFERROR(F17/(F17+F20),"") | G26: =+IFERROR(G17/(G17+G20),"") | H26: =+IFERROR(H17/(H17+H20),"") | I26: =+IFERROR(I17/(I17+I20),"") | ... M26: =+IFERROR(M17/(M17+M20),"") | O26: % EJECUCIÓN ANUAL IM≥12 | P26: =+P20/P17 -> 0
A27: % EJECUCIÓN MP IM≥12 MENSUAL | B27: =+IFERROR(B18/(B18+B21),"") | C27: =+IFERROR(C18/(C18+C21),"") | D27: =+IFERROR(D18/(D18+D21),"") | E27: =+IFERROR(E18/(E18+E21),"") | F27: =+IFERROR(F18/(F18+F21),"") | G27: =+IFERROR(G18/(G18+G21),"") | H27: =+IFERROR(H18/(H18+H21),"") | I27: =+IFERROR(I18/(I18+I21),"") | ... M27: =+IFERROR(M18/(M18+M21),"")
A29: GASTO PROGRAMADO MP | B29: 2160000000
A31: GASTO PROGRAMADO MC | B31: 960000000
A33: EJECUCIÓN GASTO MP | B33: =+SUM('SEGUIMIENTO GASTO'!AI8:AI100) -> 0
A35: EJECUCIÓN GASTO MC | B35: =+SUM('SEGUIMIENTO GASTO CORRECTIVO'!AG8:AG304) -> 0
A37: % EJECUCIÓN DEL GASTO MP | B37: =+IFERROR(B33/B29,"") -> 0 | D37: =1-B37 -> 1
A39: % EJECUCIÓN DEL GASTO MC | B39: =+IFERROR(B35/B31,"") -> 0 | D39: =1-B39 -> 1
A42: Etiquetas de fila | B42: Suma de COSTO ANUAL DE MANTENIMIENTO SEGÚN CONVENIO / PRECIO DE REFERENCIA MANTENIMIENTO ANUAL
A43: 2023 | B43: 4650000
A44: 2024 | B44: 1250000
A45: 2025 | B45: 78000000
A46: (en blanco)
A47: Total general | B47: 83900000
A49: Etiquetas de fila | B49: Suma de FRECUENCIA ANUAL DE MANTENIMIENTO
A50: 2023 | B50: 10
A51: CRÍTICO | B51: 6
A52: IM ≥ 12 | B52: 3
A53: RELEVANTE | B53: 1
A54: 2024 | B54: 4
...

Sheet Vida útil
C3: Cabe señalar, que la vida útil que se expresa en esta tabla es solo de referencia ya que existen aspectos a considerar que hacen variar este numero, por ejemplo si es estacionario o móvil, si posee usuario único o es compartido, ubicación geográfica (humedad, salinidad del aire), etc.
C8: Equipo | D8: Vida útil estimada
C9: Ablandador de agua | D9: 8
C10: Acelerador de infusión | D10: 6
C11: Acelerador Lineal | D11: 10
C12: Agitador de pipetas glóbulos | D12: 8
C13: Agitador Hematológico | D13: 8
C14: Agitador magnético | D14: 10
C15: Aireador oxido de etileno | D15: 10
C16: Alicate Corte Termoplástico | D16: 5
C17: Almohadilla prono en espuma. Medidas: 25x30x10 cms. Lavable, atoxicó | D17: 5
C18: Alza Ropa Metálico | D18: 10
C19: Amalgamador | D19: 8
C20: Analizador Bioquimico | D20: 8
... C330: Vitrector Polo Posterior | D330: 8
